import {
  throwError,
  throwCustomError,
  resolveValue,
  MyAwesomeError,
  rejectCustomError,
} from './index';

describe('resolveValue', () => {
  test('should resolve provided value', async () => {
    expect(await resolveValue('value')).toBe('value');
  });
});

describe('throwError', () => {
  test('should throw error with provided message', () => {
    const errorMsg = 'Not found';
    expect(() => throwError(errorMsg)).toThrow(errorMsg);
  });

  test('should throw error with default message if message is not provided', () => {
    expect(() => throwError()).toThrow('Oops!');
  });
});

describe('throwCustomError', () => {
  test('should throw custom error', () => {
    expect(() => throwCustomError()).toThrow(MyAwesomeError);
  });
});

describe('rejectCustomError', () => {
  test('should reject custom error', async () => {
    await expect(rejectCustomError()).rejects.toThrow(MyAwesomeError);
  });
});
